Python 3.11.4 (tags/v3.11.4:d2340ef, Jun  7 2023, 05:45:37) [MSC v.1934 64 bit (AMD64)] on win32
Type "help", "copyright", "credits" or "license()" for more information.

= RESTART: C:\Users\avandenheuvel\AppData\Local\Programs\Python\Python311\GUI test 1.31.py
Exception in Tkinter callback
Traceback (most recent call last):
  File "C:\Users\avandenheuvel\AppData\Local\Programs\Python\Python311\Lib\tkinter\__init__.py", line 1948, in __call__
    return self.func(*args)
           ^^^^^^^^^^^^^^^^
  File "C:\Users\avandenheuvel\AppData\Local\Programs\Python\Python311\GUI test 1.31.py", line 217, in on_slider_change
    self.time_period = int(value)
                       ^^^^^^^^^^
ValueError: invalid literal for int() with base 10: '80.86021505376344'
Exception in Tkinter callback
Traceback (most recent call last):
  File "C:\Users\avandenheuvel\AppData\Local\Programs\Python\Python311\Lib\tkinter\__init__.py", line 1948, in __call__
    return self.func(*args)
           ^^^^^^^^^^^^^^^^
  File "C:\Users\avandenheuvel\AppData\Local\Programs\Python\Python311\GUI test 1.31.py", line 217, in on_slider_change
    self.time_period = int(value)
                       ^^^^^^^^^^
ValueError: invalid literal for int() with base 10: '112.15053763440861'
Exception in Tkinter callback
Traceback (most recent call last):
  File "C:\Users\avandenheuvel\AppData\Local\Programs\Python\Python311\Lib\tkinter\__init__.py", line 1948, in __call__
    return self.func(*args)
           ^^^^^^^^^^^^^^^^
  File "C:\Users\avandenheuvel\AppData\Local\Programs\Python\Python311\GUI test 1.31.py", line 217, in on_slider_change
    self.time_period = int(value)
                       ^^^^^^^^^^
ValueError: invalid literal for int() with base 10: '185.16129032258064'
Exception in Tkinter callback
Traceback (most recent call last):
  File "C:\Users\avandenheuvel\AppData\Local\Programs\Python\Python311\Lib\tkinter\__init__.py", line 1948, in __call__
    return self.func(*args)
           ^^^^^^^^^^^^^^^^
  File "C:\Users\avandenheuvel\AppData\Local\Programs\Python\Python311\GUI test 1.31.py", line 217, in on_slider_change
    self.time_period = int(value)
                       ^^^^^^^^^^
ValueError: invalid literal for int() with base 10: '320.752688172043'
Exception in Tkinter callback
Traceback (most recent call last):
  File "C:\Users\avandenheuvel\AppData\Local\Programs\Python\Python311\Lib\tkinter\__init__.py", line 1948, in __call__
    return self.func(*args)
           ^^^^^^^^^^^^^^^^
  File "C:\Users\avandenheuvel\AppData\Local\Programs\Python\Python311\GUI test 1.31.py", line 217, in on_slider_change
    self.time_period = int(value)
                       ^^^^^^^^^^
ValueError: invalid literal for int() with base 10: '487.63440860215053'
Exception in Tkinter callback
Traceback (most recent call last):
  File "C:\Users\avandenheuvel\AppData\Local\Programs\Python\Python311\Lib\tkinter\__init__.py", line 1948, in __call__
    return self.func(*args)
           ^^^^^^^^^^^^^^^^
  File "C:\Users\avandenheuvel\AppData\Local\Programs\Python\Python311\GUI test 1.31.py", line 217, in on_slider_change
    self.time_period = int(value)
                       ^^^^^^^^^^
ValueError: invalid literal for int() with base 10: '779.6774193548387'
Exception in Tkinter callback
Traceback (most recent call last):
  File "C:\Users\avandenheuvel\AppData\Local\Programs\Python\Python311\Lib\tkinter\__init__.py", line 1948, in __call__
    return self.func(*args)
           ^^^^^^^^^^^^^^^^
  File "C:\Users\avandenheuvel\AppData\Local\Programs\Python\Python311\GUI test 1.31.py", line 217, in on_slider_change
    self.time_period = int(value)
                       ^^^^^^^^^^
ValueError: invalid literal for int() with base 10: '967.4193548387096'
Exception in Tkinter callback
Traceback (most recent call last):
  File "C:\Users\avandenheuvel\AppData\Local\Programs\Python\Python311\Lib\tkinter\__init__.py", line 1948, in __call__
    return self.func(*args)
           ^^^^^^^^^^^^^^^^
  File "C:\Users\avandenheuvel\AppData\Local\Programs\Python\Python311\GUI test 1.31.py", line 217, in on_slider_change
    self.time_period = int(value)
                       ^^^^^^^^^^
ValueError: invalid literal for int() with base 10: '1009.1397849462365'
Exception in Tkinter callback
Traceback (most recent call last):
  File "C:\Users\avandenheuvel\AppData\Local\Programs\Python\Python311\Lib\tkinter\__init__.py", line 1948, in __call__
    return self.func(*args)
           ^^^^^^^^^^^^^^^^
  File "C:\Users\avandenheuvel\AppData\Local\Programs\Python\Python311\GUI test 1.31.py", line 217, in on_slider_change
    self.time_period = int(value)
                       ^^^^^^^^^^
ValueError: invalid literal for int() with base 10: '1040.4301075268818'
Exception in Tkinter callback
Traceback (most recent call last):
  File "C:\Users\avandenheuvel\AppData\Local\Programs\Python\Python311\Lib\tkinter\__init__.py", line 1948, in __call__
    return self.func(*args)
           ^^^^^^^^^^^^^^^^
  File "C:\Users\avandenheuvel\AppData\Local\Programs\Python\Python311\GUI test 1.31.py", line 217, in on_slider_change
    self.time_period = int(value)
                       ^^^^^^^^^^
ValueError: invalid literal for int() with base 10: '1488.9247311827958'
Exception in Tkinter callback
Traceback (most recent call last):
  File "C:\Users\avandenheuvel\AppData\Local\Programs\Python\Python311\Lib\tkinter\__init__.py", line 1948, in __call__
    return self.func(*args)
           ^^^^^^^^^^^^^^^^
  File "C:\Users\avandenheuvel\AppData\Local\Programs\Python\Python311\GUI test 1.31.py", line 217, in on_slider_change
    self.time_period = int(value)
                       ^^^^^^^^^^
ValueError: invalid literal for int() with base 10: '1655.8064516129034'
Exception in Tkinter callback
Traceback (most recent call last):
  File "C:\Users\avandenheuvel\AppData\Local\Programs\Python\Python311\Lib\tkinter\__init__.py", line 1948, in __call__
    return self.func(*args)
           ^^^^^^^^^^^^^^^^
  File "C:\Users\avandenheuvel\AppData\Local\Programs\Python\Python311\GUI test 1.31.py", line 217, in on_slider_change
    self.time_period = int(value)
                       ^^^^^^^^^^
ValueError: invalid literal for int() with base 10: '1707.9569892473119'
Exception in Tkinter callback
Traceback (most recent call last):
  File "C:\Users\avandenheuvel\AppData\Local\Programs\Python\Python311\Lib\tkinter\__init__.py", line 1948, in __call__
    return self.func(*args)
           ^^^^^^^^^^^^^^^^
  File "C:\Users\avandenheuvel\AppData\Local\Programs\Python\Python311\GUI test 1.31.py", line 217, in on_slider_change
    self.time_period = int(value)
                       ^^^^^^^^^^
ValueError: invalid literal for int() with base 10: '1697.52688172043'
Exception in Tkinter callback
Traceback (most recent call last):
  File "C:\Users\avandenheuvel\AppData\Local\Programs\Python\Python311\Lib\tkinter\__init__.py", line 1948, in __call__
    return self.func(*args)
           ^^^^^^^^^^^^^^^^
  File "C:\Users\avandenheuvel\AppData\Local\Programs\Python\Python311\GUI test 1.31.py", line 217, in on_slider_change
    self.time_period = int(value)
                       ^^^^^^^^^^
ValueError: invalid literal for int() with base 10: '1530.6451612903227'
Exception in Tkinter callback
Traceback (most recent call last):
  File "C:\Users\avandenheuvel\AppData\Local\Programs\Python\Python311\Lib\tkinter\__init__.py", line 1948, in __call__
    return self.func(*args)
           ^^^^^^^^^^^^^^^^
  File "C:\Users\avandenheuvel\AppData\Local\Programs\Python\Python311\GUI test 1.31.py", line 217, in on_slider_change
    self.time_period = int(value)
                       ^^^^^^^^^^
ValueError: invalid literal for int() with base 10: '1405.483870967742'
Exception in Tkinter callback
Traceback (most recent call last):
  File "C:\Users\avandenheuvel\AppData\Local\Programs\Python\Python311\Lib\tkinter\__init__.py", line 1948, in __call__
    return self.func(*args)
           ^^^^^^^^^^^^^^^^
  File "C:\Users\avandenheuvel\AppData\Local\Programs\Python\Python311\GUI test 1.31.py", line 217, in on_slider_change
    self.time_period = int(value)
                       ^^^^^^^^^^
ValueError: invalid literal for int() with base 10: '1290.752688172043'
Exception in Tkinter callback
Traceback (most recent call last):
  File "C:\Users\avandenheuvel\AppData\Local\Programs\Python\Python311\Lib\tkinter\__init__.py", line 1948, in __call__
    return self.func(*args)
           ^^^^^^^^^^^^^^^^
  File "C:\Users\avandenheuvel\AppData\Local\Programs\Python\Python311\GUI test 1.31.py", line 217, in on_slider_change
    self.time_period = int(value)
                       ^^^^^^^^^^
ValueError: invalid literal for int() with base 10: '1061.2903225806451'
Exception in Tkinter callback
Traceback (most recent call last):
  File "C:\Users\avandenheuvel\AppData\Local\Programs\Python\Python311\Lib\tkinter\__init__.py", line 1948, in __call__
    return self.func(*args)
           ^^^^^^^^^^^^^^^^
  File "C:\Users\avandenheuvel\AppData\Local\Programs\Python\Python311\GUI test 1.31.py", line 217, in on_slider_change
    self.time_period = int(value)
                       ^^^^^^^^^^
ValueError: invalid literal for int() with base 10: '664.9462365591398'
Exception in Tkinter callback
Traceback (most recent call last):
  File "C:\Users\avandenheuvel\AppData\Local\Programs\Python\Python311\Lib\tkinter\__init__.py", line 1948, in __call__
    return self.func(*args)
           ^^^^^^^^^^^^^^^^
  File "C:\Users\avandenheuvel\AppData\Local\Programs\Python\Python311\GUI test 1.31.py", line 217, in on_slider_change
    self.time_period = int(value)
                       ^^^^^^^^^^
ValueError: invalid literal for int() with base 10: '571.0752688172042'
Exception in Tkinter callback
Traceback (most recent call last):
  File "C:\Users\avandenheuvel\AppData\Local\Programs\Python\Python311\Lib\tkinter\__init__.py", line 1948, in __call__
    return self.func(*args)
           ^^^^^^^^^^^^^^^^
  File "C:\Users\avandenheuvel\AppData\Local\Programs\Python\Python311\GUI test 1.31.py", line 217, in on_slider_change
    self.time_period = int(value)
                       ^^^^^^^^^^
ValueError: invalid literal for int() with base 10: '508.494623655914'
Exception in Tkinter callback
Traceback (most recent call last):
  File "C:\Users\avandenheuvel\AppData\Local\Programs\Python\Python311\Lib\tkinter\__init__.py", line 1948, in __call__
    return self.func(*args)
           ^^^^^^^^^^^^^^^^
  File "C:\Users\avandenheuvel\AppData\Local\Programs\Python\Python311\GUI test 1.31.py", line 217, in on_slider_change
    self.time_period = int(value)
                       ^^^^^^^^^^
ValueError: invalid literal for int() with base 10: '508.494623655914'
Exception in Tkinter callback
Traceback (most recent call last):
  File "C:\Users\avandenheuvel\AppData\Local\Programs\Python\Python311\Lib\tkinter\__init__.py", line 1948, in __call__
    return self.func(*args)
           ^^^^^^^^^^^^^^^^
  File "C:\Users\avandenheuvel\AppData\Local\Programs\Python\Python311\GUI test 1.31.py", line 217, in on_slider_change
    self.time_period = int(value)
                       ^^^^^^^^^^
ValueError: invalid literal for int() with base 10: '122.58064516129032'
Exception in Tkinter callback
Traceback (most recent call last):
  File "C:\Users\avandenheuvel\AppData\Local\Programs\Python\Python311\Lib\tkinter\__init__.py", line 1948, in __call__
    return self.func(*args)
           ^^^^^^^^^^^^^^^^
  File "C:\Users\avandenheuvel\AppData\Local\Programs\Python\Python311\GUI test 1.31.py", line 217, in on_slider_change
    self.time_period = int(value)
                       ^^^^^^^^^^
ValueError: invalid literal for int() with base 10: '60.0'
Exception in Tkinter callback
Traceback (most recent call last):
  File "C:\Users\avandenheuvel\AppData\Local\Programs\Python\Python311\Lib\tkinter\__init__.py", line 1948, in __call__
    return self.func(*args)
           ^^^^^^^^^^^^^^^^
  File "C:\Users\avandenheuvel\AppData\Local\Programs\Python\Python311\GUI test 1.31.py", line 217, in on_slider_change
    self.time_period = int(value)
                       ^^^^^^^^^^
ValueError: invalid literal for int() with base 10: '80.86021505376344'
Exception in Tkinter callback
Traceback (most recent call last):
  File "C:\Users\avandenheuvel\AppData\Local\Programs\Python\Python311\Lib\tkinter\__init__.py", line 1948, in __call__
    return self.func(*args)
           ^^^^^^^^^^^^^^^^
  File "C:\Users\avandenheuvel\AppData\Local\Programs\Python\Python311\GUI test 1.31.py", line 217, in on_slider_change
    self.time_period = int(value)
                       ^^^^^^^^^^
ValueError: invalid literal for int() with base 10: '863.1182795698925'
Exception in Tkinter callback
Traceback (most recent call last):
  File "C:\Users\avandenheuvel\AppData\Local\Programs\Python\Python311\Lib\tkinter\__init__.py", line 1948, in __call__
    return self.func(*args)
           ^^^^^^^^^^^^^^^^
  File "C:\Users\avandenheuvel\AppData\Local\Programs\Python\Python311\GUI test 1.31.py", line 217, in on_slider_change
    self.time_period = int(value)
                       ^^^^^^^^^^
ValueError: invalid literal for int() with base 10: '1165.5913978494625'
Exception in Tkinter callback
Traceback (most recent call last):
  File "C:\Users\avandenheuvel\AppData\Local\Programs\Python\Python311\Lib\tkinter\__init__.py", line 1948, in __call__
    return self.func(*args)
           ^^^^^^^^^^^^^^^^
  File "C:\Users\avandenheuvel\AppData\Local\Programs\Python\Python311\GUI test 1.31.py", line 217, in on_slider_change
    self.time_period = int(value)
                       ^^^^^^^^^^
ValueError: invalid literal for int() with base 10: '1249.032258064516'
Exception in Tkinter callback
Traceback (most recent call last):
  File "C:\Users\avandenheuvel\AppData\Local\Programs\Python\Python311\Lib\tkinter\__init__.py", line 1948, in __call__
    return self.func(*args)
           ^^^^^^^^^^^^^^^^
  File "C:\Users\avandenheuvel\AppData\Local\Programs\Python\Python311\GUI test 1.31.py", line 217, in on_slider_change
    self.time_period = int(value)
                       ^^^^^^^^^^
ValueError: invalid literal for int() with base 10: '1322.0430107526881'
Exception in Tkinter callback
Traceback (most recent call last):
  File "C:\Users\avandenheuvel\AppData\Local\Programs\Python\Python311\Lib\tkinter\__init__.py", line 1948, in __call__
    return self.func(*args)
           ^^^^^^^^^^^^^^^^
  File "C:\Users\avandenheuvel\AppData\Local\Programs\Python\Python311\GUI test 1.31.py", line 217, in on_slider_change
    self.time_period = int(value)
                       ^^^^^^^^^^
ValueError: invalid literal for int() with base 10: '1603.6559139784945'
Exception in Tkinter callback
Traceback (most recent call last):
  File "C:\Users\avandenheuvel\AppData\Local\Programs\Python\Python311\Lib\tkinter\__init__.py", line 1948, in __call__
    return self.func(*args)
           ^^^^^^^^^^^^^^^^
  File "C:\Users\avandenheuvel\AppData\Local\Programs\Python\Python311\GUI test 1.31.py", line 217, in on_slider_change
    self.time_period = int(value)
                       ^^^^^^^^^^
ValueError: invalid literal for int() with base 10: '1760.1075268817203'
Exception in Tkinter callback
Traceback (most recent call last):
  File "C:\Users\avandenheuvel\AppData\Local\Programs\Python\Python311\Lib\tkinter\__init__.py", line 1948, in __call__
    return self.func(*args)
           ^^^^^^^^^^^^^^^^
  File "C:\Users\avandenheuvel\AppData\Local\Programs\Python\Python311\GUI test 1.31.py", line 217, in on_slider_change
    self.time_period = int(value)
                       ^^^^^^^^^^
ValueError: invalid literal for int() with base 10: '1749.6774193548388'
Exception in Tkinter callback
Traceback (most recent call last):
  File "C:\Users\avandenheuvel\AppData\Local\Programs\Python\Python311\Lib\tkinter\__init__.py", line 1948, in __call__
    return self.func(*args)
           ^^^^^^^^^^^^^^^^
  File "C:\Users\avandenheuvel\AppData\Local\Programs\Python\Python311\GUI test 1.31.py", line 217, in on_slider_change
    self.time_period = int(value)
                       ^^^^^^^^^^
ValueError: invalid literal for int() with base 10: '1603.6559139784945'
Exception in Tkinter callback
Traceback (most recent call last):
  File "C:\Users\avandenheuvel\AppData\Local\Programs\Python\Python311\Lib\tkinter\__init__.py", line 1948, in __call__
    return self.func(*args)
           ^^^^^^^^^^^^^^^^
  File "C:\Users\avandenheuvel\AppData\Local\Programs\Python\Python311\GUI test 1.31.py", line 217, in on_slider_change
    self.time_period = int(value)
                       ^^^^^^^^^^
ValueError: invalid literal for int() with base 10: '1593.225806451613'
Exception in Tkinter callback
Traceback (most recent call last):
  File "C:\Users\avandenheuvel\AppData\Local\Programs\Python\Python311\Lib\tkinter\__init__.py", line 1948, in __call__
    return self.func(*args)
           ^^^^^^^^^^^^^^^^
  File "C:\Users\avandenheuvel\AppData\Local\Programs\Python\Python311\GUI test 1.31.py", line 217, in on_slider_change
    self.time_period = int(value)
                       ^^^^^^^^^^
ValueError: invalid literal for int() with base 10: '1718.3870967741937'
Exception in Tkinter callback
Traceback (most recent call last):
  File "C:\Users\avandenheuvel\AppData\Local\Programs\Python\Python311\Lib\tkinter\__init__.py", line 1948, in __call__
    return self.func(*args)
           ^^^^^^^^^^^^^^^^
  File "C:\Users\avandenheuvel\AppData\Local\Programs\Python\Python311\GUI test 1.31.py", line 217, in on_slider_change
    self.time_period = int(value)
                       ^^^^^^^^^^
ValueError: invalid literal for int() with base 10: '2000.0'
Exception in Tkinter callback
Traceback (most recent call last):
  File "C:\Users\avandenheuvel\AppData\Local\Programs\Python\Python311\Lib\tkinter\__init__.py", line 1948, in __call__
    return self.func(*args)
           ^^^^^^^^^^^^^^^^
  File "C:\Users\avandenheuvel\AppData\Local\Programs\Python\Python311\GUI test 1.31.py", line 217, in on_slider_change
    self.time_period = int(value)
                       ^^^^^^^^^^
ValueError: invalid literal for int() with base 10: '2000.0'
Exception in Tkinter callback
Traceback (most recent call last):
  File "C:\Users\avandenheuvel\AppData\Local\Programs\Python\Python311\Lib\tkinter\__init__.py", line 1948, in __call__
    return self.func(*args)
           ^^^^^^^^^^^^^^^^
  File "C:\Users\avandenheuvel\AppData\Local\Programs\Python\Python311\GUI test 1.31.py", line 217, in on_slider_change
    self.time_period = int(value)
                       ^^^^^^^^^^
ValueError: invalid literal for int() with base 10: '2000.0'
Exception in Tkinter callback
Traceback (most recent call last):
  File "C:\Users\avandenheuvel\AppData\Local\Programs\Python\Python311\Lib\tkinter\__init__.py", line 1948, in __call__
    return self.func(*args)
           ^^^^^^^^^^^^^^^^
  File "C:\Users\avandenheuvel\AppData\Local\Programs\Python\Python311\GUI test 1.31.py", line 217, in on_slider_change
    self.time_period = int(value)
                       ^^^^^^^^^^
ValueError: invalid literal for int() with base 10: '2000.0'
Exception in Tkinter callback
Traceback (most recent call last):
  File "C:\Users\avandenheuvel\AppData\Local\Programs\Python\Python311\Lib\tkinter\__init__.py", line 1948, in __call__
    return self.func(*args)
           ^^^^^^^^^^^^^^^^
  File "C:\Users\avandenheuvel\AppData\Local\Programs\Python\Python311\GUI test 1.31.py", line 217, in on_slider_change
    self.time_period = int(value)
                       ^^^^^^^^^^
ValueError: invalid literal for int() with base 10: '2000.0'
Exception in Tkinter callback
Traceback (most recent call last):
  File "C:\Users\avandenheuvel\AppData\Local\Programs\Python\Python311\Lib\tkinter\__init__.py", line 1948, in __call__
    return self.func(*args)
           ^^^^^^^^^^^^^^^^
  File "C:\Users\avandenheuvel\AppData\Local\Programs\Python\Python311\GUI test 1.31.py", line 217, in on_slider_change
    self.time_period = int(value)
                       ^^^^^^^^^^
ValueError: invalid literal for int() with base 10: '1071.7204301075267'
Exception in Tkinter callback
Traceback (most recent call last):
  File "C:\Users\avandenheuvel\AppData\Local\Programs\Python\Python311\Lib\tkinter\__init__.py", line 1948, in __call__
    return self.func(*args)
           ^^^^^^^^^^^^^^^^
  File "C:\Users\avandenheuvel\AppData\Local\Programs\Python\Python311\GUI test 1.31.py", line 217, in on_slider_change
    self.time_period = int(value)
                       ^^^^^^^^^^
ValueError: invalid literal for int() with base 10: '894.4086021505376'
Exception in Tkinter callback
Traceback (most recent call last):
  File "C:\Users\avandenheuvel\AppData\Local\Programs\Python\Python311\Lib\tkinter\__init__.py", line 1948, in __call__
    return self.func(*args)
           ^^^^^^^^^^^^^^^^
  File "C:\Users\avandenheuvel\AppData\Local\Programs\Python\Python311\GUI test 1.31.py", line 217, in on_slider_change
    self.time_period = int(value)
                       ^^^^^^^^^^
ValueError: invalid literal for int() with base 10: '800.5376344086021'
Exception in Tkinter callback
Traceback (most recent call last):
  File "C:\Users\avandenheuvel\AppData\Local\Programs\Python\Python311\Lib\tkinter\__init__.py", line 1948, in __call__
    return self.func(*args)
           ^^^^^^^^^^^^^^^^
  File "C:\Users\avandenheuvel\AppData\Local\Programs\Python\Python311\GUI test 1.31.py", line 217, in on_slider_change
    self.time_period = int(value)
                       ^^^^^^^^^^
ValueError: invalid literal for int() with base 10: '675.3763440860215'
Exception in Tkinter callback
Traceback (most recent call last):
  File "C:\Users\avandenheuvel\AppData\Local\Programs\Python\Python311\Lib\tkinter\__init__.py", line 1948, in __call__
    return self.func(*args)
           ^^^^^^^^^^^^^^^^
  File "C:\Users\avandenheuvel\AppData\Local\Programs\Python\Python311\GUI test 1.31.py", line 217, in on_slider_change
    self.time_period = int(value)
                       ^^^^^^^^^^
ValueError: invalid literal for int() with base 10: '518.9247311827958'
Exception in Tkinter callback
Traceback (most recent call last):
  File "C:\Users\avandenheuvel\AppData\Local\Programs\Python\Python311\Lib\tkinter\__init__.py", line 1948, in __call__
    return self.func(*args)
           ^^^^^^^^^^^^^^^^
  File "C:\Users\avandenheuvel\AppData\Local\Programs\Python\Python311\GUI test 1.31.py", line 217, in on_slider_change
    self.time_period = int(value)
                       ^^^^^^^^^^
ValueError: invalid literal for int() with base 10: '372.9032258064516'
Exception in Tkinter callback
Traceback (most recent call last):
  File "C:\Users\avandenheuvel\AppData\Local\Programs\Python\Python311\Lib\tkinter\__init__.py", line 1948, in __call__
    return self.func(*args)
           ^^^^^^^^^^^^^^^^
  File "C:\Users\avandenheuvel\AppData\Local\Programs\Python\Python311\GUI test 1.31.py", line 217, in on_slider_change
    self.time_period = int(value)
                       ^^^^^^^^^^
ValueError: invalid literal for int() with base 10: '299.89247311827955'
Exception in Tkinter callback
Traceback (most recent call last):
  File "C:\Users\avandenheuvel\AppData\Local\Programs\Python\Python311\Lib\tkinter\__init__.py", line 1948, in __call__
    return self.func(*args)
           ^^^^^^^^^^^^^^^^
  File "C:\Users\avandenheuvel\AppData\Local\Programs\Python\Python311\GUI test 1.31.py", line 217, in on_slider_change
    self.time_period = int(value)
                       ^^^^^^^^^^
ValueError: invalid literal for int() with base 10: '237.31182795698925'
Exception in Tkinter callback
Traceback (most recent call last):
  File "C:\Users\avandenheuvel\AppData\Local\Programs\Python\Python311\Lib\tkinter\__init__.py", line 1948, in __call__
    return self.func(*args)
           ^^^^^^^^^^^^^^^^
  File "C:\Users\avandenheuvel\AppData\Local\Programs\Python\Python311\GUI test 1.31.py", line 217, in on_slider_change
    self.time_period = int(value)
                       ^^^^^^^^^^
ValueError: invalid literal for int() with base 10: '185.16129032258064'
Exception in Tkinter callback
Traceback (most recent call last):
  File "C:\Users\avandenheuvel\AppData\Local\Programs\Python\Python311\Lib\tkinter\__init__.py", line 1948, in __call__
    return self.func(*args)
           ^^^^^^^^^^^^^^^^
  File "C:\Users\avandenheuvel\AppData\Local\Programs\Python\Python311\GUI test 1.31.py", line 217, in on_slider_change
    self.time_period = int(value)
                       ^^^^^^^^^^
ValueError: invalid literal for int() with base 10: '91.29032258064515'
Exception in Tkinter callback
Traceback (most recent call last):
  File "C:\Users\avandenheuvel\AppData\Local\Programs\Python\Python311\Lib\tkinter\__init__.py", line 1948, in __call__
    return self.func(*args)
           ^^^^^^^^^^^^^^^^
  File "C:\Users\avandenheuvel\AppData\Local\Programs\Python\Python311\GUI test 1.31.py", line 217, in on_slider_change
    self.time_period = int(value)
                       ^^^^^^^^^^
ValueError: invalid literal for int() with base 10: '60.0'

= RESTART: C:\Users\avandenheuvel\AppData\Local\Programs\Python\Python311\GUI test 1.31.py
Exception in Tkinter callback
Traceback (most recent call last):
  File "C:\Users\avandenheuvel\AppData\Local\Programs\Python\Python311\Lib\tkinter\__init__.py", line 1948, in __call__
    return self.func(*args)
           ^^^^^^^^^^^^^^^^
  File "C:\Users\avandenheuvel\AppData\Local\Programs\Python\Python311\GUI test 1.31.py", line 218, in on_slider_change
    self.update_graph()
  File "C:\Users\avandenheuvel\AppData\Local\Programs\Python\Python311\GUI test 1.31.py", line 206, in update_graph
    self.graph_ax.plot(self.time_values[-self.time_period.get():], self.temperature_values[-self.time_period.get():], label='Temperature')
                                         ^^^^^^^^^^^^^^^^^^^^
AttributeError: 'int' object has no attribute 'get'
Exception in Tkinter callback
Traceback (most recent call last):
  File "C:\Users\avandenheuvel\AppData\Local\Programs\Python\Python311\Lib\tkinter\__init__.py", line 1948, in __call__
    return self.func(*args)
           ^^^^^^^^^^^^^^^^
  File "C:\Users\avandenheuvel\AppData\Local\Programs\Python\Python311\GUI test 1.31.py", line 218, in on_slider_change
    self.update_graph()
  File "C:\Users\avandenheuvel\AppData\Local\Programs\Python\Python311\GUI test 1.31.py", line 206, in update_graph
    self.graph_ax.plot(self.time_values[-self.time_period.get():], self.temperature_values[-self.time_period.get():], label='Temperature')
                                         ^^^^^^^^^^^^^^^^^^^^
AttributeError: 'int' object has no attribute 'get'
Exception in Tkinter callback
Traceback (most recent call last):
  File "C:\Users\avandenheuvel\AppData\Local\Programs\Python\Python311\Lib\tkinter\__init__.py", line 1948, in __call__
    return self.func(*args)
           ^^^^^^^^^^^^^^^^
  File "C:\Users\avandenheuvel\AppData\Local\Programs\Python\Python311\GUI test 1.31.py", line 218, in on_slider_change
    self.update_graph()
  File "C:\Users\avandenheuvel\AppData\Local\Programs\Python\Python311\GUI test 1.31.py", line 206, in update_graph
    self.graph_ax.plot(self.time_values[-self.time_period.get():], self.temperature_values[-self.time_period.get():], label='Temperature')
                                         ^^^^^^^^^^^^^^^^^^^^
AttributeError: 'int' object has no attribute 'get'
Exception in Tkinter callback
Traceback (most recent call last):
  File "C:\Users\avandenheuvel\AppData\Local\Programs\Python\Python311\Lib\tkinter\__init__.py", line 1948, in __call__
    return self.func(*args)
           ^^^^^^^^^^^^^^^^
  File "C:\Users\avandenheuvel\AppData\Local\Programs\Python\Python311\GUI test 1.31.py", line 218, in on_slider_change
    self.update_graph()
  File "C:\Users\avandenheuvel\AppData\Local\Programs\Python\Python311\GUI test 1.31.py", line 206, in update_graph
    self.graph_ax.plot(self.time_values[-self.time_period.get():], self.temperature_values[-self.time_period.get():], label='Temperature')
                                         ^^^^^^^^^^^^^^^^^^^^
AttributeError: 'int' object has no attribute 'get'
Exception in Tkinter callback
Traceback (most recent call last):
  File "C:\Users\avandenheuvel\AppData\Local\Programs\Python\Python311\Lib\tkinter\__init__.py", line 1948, in __call__
    return self.func(*args)
           ^^^^^^^^^^^^^^^^
  File "C:\Users\avandenheuvel\AppData\Local\Programs\Python\Python311\GUI test 1.31.py", line 218, in on_slider_change
    self.update_graph()
  File "C:\Users\avandenheuvel\AppData\Local\Programs\Python\Python311\GUI test 1.31.py", line 206, in update_graph
    self.graph_ax.plot(self.time_values[-self.time_period.get():], self.temperature_values[-self.time_period.get():], label='Temperature')
                                         ^^^^^^^^^^^^^^^^^^^^
AttributeError: 'int' object has no attribute 'get'
Exception in Tkinter callback
Traceback (most recent call last):
  File "C:\Users\avandenheuvel\AppData\Local\Programs\Python\Python311\Lib\tkinter\__init__.py", line 1948, in __call__
    return self.func(*args)
           ^^^^^^^^^^^^^^^^
  File "C:\Users\avandenheuvel\AppData\Local\Programs\Python\Python311\GUI test 1.31.py", line 218, in on_slider_change
    self.update_graph()
  File "C:\Users\avandenheuvel\AppData\Local\Programs\Python\Python311\GUI test 1.31.py", line 206, in update_graph
    self.graph_ax.plot(self.time_values[-self.time_period.get():], self.temperature_values[-self.time_period.get():], label='Temperature')
                                         ^^^^^^^^^^^^^^^^^^^^
AttributeError: 'int' object has no attribute 'get'
Exception in Tkinter callback
Traceback (most recent call last):
  File "C:\Users\avandenheuvel\AppData\Local\Programs\Python\Python311\Lib\tkinter\__init__.py", line 1948, in __call__
    return self.func(*args)
           ^^^^^^^^^^^^^^^^
  File "C:\Users\avandenheuvel\AppData\Local\Programs\Python\Python311\Lib\tkinter\__init__.py", line 861, in callit
    func(*args)
  File "C:\Users\avandenheuvel\AppData\Local\Programs\Python\Python311\GUI test 1.31.py", line 188, in update_data_simulation
    self.update_graph()
  File "C:\Users\avandenheuvel\AppData\Local\Programs\Python\Python311\GUI test 1.31.py", line 206, in update_graph
    self.graph_ax.plot(self.time_values[-self.time_period.get():], self.temperature_values[-self.time_period.get():], label='Temperature')
                                         ^^^^^^^^^^^^^^^^^^^^
AttributeError: 'int' object has no attribute 'get'
Exception in Tkinter callback
Traceback (most recent call last):
  File "C:\Users\avandenheuvel\AppData\Local\Programs\Python\Python311\Lib\tkinter\__init__.py", line 1948, in __call__
    return self.func(*args)
           ^^^^^^^^^^^^^^^^
  File "C:\Users\avandenheuvel\AppData\Local\Programs\Python\Python311\GUI test 1.31.py", line 218, in on_slider_change
    self.update_graph()
  File "C:\Users\avandenheuvel\AppData\Local\Programs\Python\Python311\GUI test 1.31.py", line 206, in update_graph
    self.graph_ax.plot(self.time_values[-self.time_period.get():], self.temperature_values[-self.time_period.get():], label='Temperature')
                                         ^^^^^^^^^^^^^^^^^^^^
AttributeError: 'int' object has no attribute 'get'
Exception in Tkinter callback
Traceback (most recent call last):
  File "C:\Users\avandenheuvel\AppData\Local\Programs\Python\Python311\Lib\tkinter\__init__.py", line 1948, in __call__
    return self.func(*args)
           ^^^^^^^^^^^^^^^^
  File "C:\Users\avandenheuvel\AppData\Local\Programs\Python\Python311\GUI test 1.31.py", line 218, in on_slider_change
    self.update_graph()
  File "C:\Users\avandenheuvel\AppData\Local\Programs\Python\Python311\GUI test 1.31.py", line 206, in update_graph
    self.graph_ax.plot(self.time_values[-self.time_period.get():], self.temperature_values[-self.time_period.get():], label='Temperature')
                                         ^^^^^^^^^^^^^^^^^^^^
AttributeError: 'int' object has no attribute 'get'
Exception in Tkinter callback
Traceback (most recent call last):
  File "C:\Users\avandenheuvel\AppData\Local\Programs\Python\Python311\Lib\tkinter\__init__.py", line 1948, in __call__
    return self.func(*args)
           ^^^^^^^^^^^^^^^^
  File "C:\Users\avandenheuvel\AppData\Local\Programs\Python\Python311\GUI test 1.31.py", line 218, in on_slider_change
    self.update_graph()
  File "C:\Users\avandenheuvel\AppData\Local\Programs\Python\Python311\GUI test 1.31.py", line 206, in update_graph
    self.graph_ax.plot(self.time_values[-self.time_period.get():], self.temperature_values[-self.time_period.get():], label='Temperature')
                                         ^^^^^^^^^^^^^^^^^^^^
AttributeError: 'int' object has no attribute 'get'
Exception in Tkinter callback
Traceback (most recent call last):
  File "C:\Users\avandenheuvel\AppData\Local\Programs\Python\Python311\Lib\tkinter\__init__.py", line 1948, in __call__
    return self.func(*args)
           ^^^^^^^^^^^^^^^^
  File "C:\Users\avandenheuvel\AppData\Local\Programs\Python\Python311\GUI test 1.31.py", line 218, in on_slider_change
    self.update_graph()
  File "C:\Users\avandenheuvel\AppData\Local\Programs\Python\Python311\GUI test 1.31.py", line 206, in update_graph
    self.graph_ax.plot(self.time_values[-self.time_period.get():], self.temperature_values[-self.time_period.get():], label='Temperature')
                                         ^^^^^^^^^^^^^^^^^^^^
AttributeError: 'int' object has no attribute 'get'
Exception in Tkinter callback
Traceback (most recent call last):
  File "C:\Users\avandenheuvel\AppData\Local\Programs\Python\Python311\Lib\tkinter\__init__.py", line 1948, in __call__
    return self.func(*args)
           ^^^^^^^^^^^^^^^^
  File "C:\Users\avandenheuvel\AppData\Local\Programs\Python\Python311\GUI test 1.31.py", line 218, in on_slider_change
    self.update_graph()
  File "C:\Users\avandenheuvel\AppData\Local\Programs\Python\Python311\GUI test 1.31.py", line 206, in update_graph
    self.graph_ax.plot(self.time_values[-self.time_period.get():], self.temperature_values[-self.time_period.get():], label='Temperature')
                                         ^^^^^^^^^^^^^^^^^^^^
AttributeError: 'int' object has no attribute 'get'
Exception in Tkinter callback
Traceback (most recent call last):
  File "C:\Users\avandenheuvel\AppData\Local\Programs\Python\Python311\Lib\tkinter\__init__.py", line 1948, in __call__
    return self.func(*args)
           ^^^^^^^^^^^^^^^^
  File "C:\Users\avandenheuvel\AppData\Local\Programs\Python\Python311\GUI test 1.31.py", line 218, in on_slider_change
    self.update_graph()
  File "C:\Users\avandenheuvel\AppData\Local\Programs\Python\Python311\GUI test 1.31.py", line 206, in update_graph
    self.graph_ax.plot(self.time_values[-self.time_period.get():], self.temperature_values[-self.time_period.get():], label='Temperature')
                                         ^^^^^^^^^^^^^^^^^^^^
AttributeError: 'int' object has no attribute 'get'
Exception in Tkinter callback
Traceback (most recent call last):
  File "C:\Users\avandenheuvel\AppData\Local\Programs\Python\Python311\Lib\tkinter\__init__.py", line 1948, in __call__
    return self.func(*args)
           ^^^^^^^^^^^^^^^^
  File "C:\Users\avandenheuvel\AppData\Local\Programs\Python\Python311\GUI test 1.31.py", line 218, in on_slider_change
    self.update_graph()
  File "C:\Users\avandenheuvel\AppData\Local\Programs\Python\Python311\GUI test 1.31.py", line 206, in update_graph
    self.graph_ax.plot(self.time_values[-self.time_period.get():], self.temperature_values[-self.time_period.get():], label='Temperature')
                                         ^^^^^^^^^^^^^^^^^^^^
AttributeError: 'int' object has no attribute 'get'
Exception in Tkinter callback
Traceback (most recent call last):
  File "C:\Users\avandenheuvel\AppData\Local\Programs\Python\Python311\Lib\tkinter\__init__.py", line 1948, in __call__
    return self.func(*args)
           ^^^^^^^^^^^^^^^^
  File "C:\Users\avandenheuvel\AppData\Local\Programs\Python\Python311\GUI test 1.31.py", line 218, in on_slider_change
    self.update_graph()
  File "C:\Users\avandenheuvel\AppData\Local\Programs\Python\Python311\GUI test 1.31.py", line 206, in update_graph
    self.graph_ax.plot(self.time_values[-self.time_period.get():], self.temperature_values[-self.time_period.get():], label='Temperature')
                                         ^^^^^^^^^^^^^^^^^^^^
AttributeError: 'int' object has no attribute 'get'
Exception in Tkinter callback
Traceback (most recent call last):
  File "C:\Users\avandenheuvel\AppData\Local\Programs\Python\Python311\Lib\tkinter\__init__.py", line 1948, in __call__
    return self.func(*args)
           ^^^^^^^^^^^^^^^^
  File "C:\Users\avandenheuvel\AppData\Local\Programs\Python\Python311\GUI test 1.31.py", line 218, in on_slider_change
    self.update_graph()
  File "C:\Users\avandenheuvel\AppData\Local\Programs\Python\Python311\GUI test 1.31.py", line 206, in update_graph
    self.graph_ax.plot(self.time_values[-self.time_period.get():], self.temperature_values[-self.time_period.get():], label='Temperature')
                                         ^^^^^^^^^^^^^^^^^^^^
AttributeError: 'int' object has no attribute 'get'
Exception in Tkinter callback
Traceback (most recent call last):
  File "C:\Users\avandenheuvel\AppData\Local\Programs\Python\Python311\Lib\tkinter\__init__.py", line 1948, in __call__
    return self.func(*args)
           ^^^^^^^^^^^^^^^^
  File "C:\Users\avandenheuvel\AppData\Local\Programs\Python\Python311\GUI test 1.31.py", line 218, in on_slider_change
    self.update_graph()
  File "C:\Users\avandenheuvel\AppData\Local\Programs\Python\Python311\GUI test 1.31.py", line 206, in update_graph
    self.graph_ax.plot(self.time_values[-self.time_period.get():], self.temperature_values[-self.time_period.get():], label='Temperature')
                                         ^^^^^^^^^^^^^^^^^^^^
AttributeError: 'int' object has no attribute 'get'

= RESTART: C:\Users\avandenheuvel\AppData\Local\Programs\Python\Python311\GUI test 1.31.py
Exception in Tkinter callback
Traceback (most recent call last):
  File "C:\Users\avandenheuvel\AppData\Local\Programs\Python\Python311\Lib\tkinter\__init__.py", line 1948, in __call__
    return self.func(*args)
           ^^^^^^^^^^^^^^^^
  File "C:\Users\avandenheuvel\AppData\Local\Programs\Python\Python311\Lib\tkinter\__init__.py", line 861, in callit
    func(*args)
  File "C:\Users\avandenheuvel\AppData\Local\Programs\Python\Python311\GUI test 1.31.py", line 188, in update_data_simulation
    self.update_graph()
  File "C:\Users\avandenheuvel\AppData\Local\Programs\Python\Python311\GUI test 1.31.py", line 206, in update_graph
    self.graph_ax.plot(self.time_values[-self.time_period:], self.temperature_values[-self.time_period:], label='Temperature')
                                        ^^^^^^^^^^^^^^^^^
TypeError: bad operand type for unary -: 'IntVar'

= RESTART: C:\Users\avandenheuvel\AppData\Local\Programs\Python\Python311\GUI test 1.31.py
Exception in Tkinter callback
Traceback (most recent call last):
  File "C:\Users\avandenheuvel\AppData\Local\Programs\Python\Python311\Lib\tkinter\__init__.py", line 1948, in __call__
    return self.func(*args)
           ^^^^^^^^^^^^^^^^
  File "C:\Users\avandenheuvel\AppData\Local\Programs\Python\Python311\Lib\tkinter\__init__.py", line 861, in callit
    func(*args)
  File "C:\Users\avandenheuvel\AppData\Local\Programs\Python\Python311\GUI test 1.31.py", line 188, in update_data_simulation
    self.update_graph()
  File "C:\Users\avandenheuvel\AppData\Local\Programs\Python\Python311\GUI test 1.31.py", line 206, in update_graph
    self.graph_ax.plot(self.time_values[-self.time_period:], self.temperature_values[-self.time_period:], label='Temperature')
                                        ^^^^^^^^^^^^^^^^^
TypeError: bad operand type for unary -: 'IntVar'

= RESTART: C:\Users\avandenheuvel\AppData\Local\Programs\Python\Python311\GUI test 1.31.py
Exception in Tkinter callback
Traceback (most recent call last):
  File "C:\Users\avandenheuvel\AppData\Local\Programs\Python\Python311\Lib\tkinter\__init__.py", line 1948, in __call__
    return self.func(*args)
           ^^^^^^^^^^^^^^^^
  File "C:\Users\avandenheuvel\AppData\Local\Programs\Python\Python311\GUI test 1.31.py", line 217, in on_slider_change
    self.time_period = int(value)
                       ^^^^^^^^^^
ValueError: invalid literal for int() with base 10: '91.29032258064515'
Exception in Tkinter callback
Traceback (most recent call last):
  File "C:\Users\avandenheuvel\AppData\Local\Programs\Python\Python311\Lib\tkinter\__init__.py", line 1948, in __call__
    return self.func(*args)
           ^^^^^^^^^^^^^^^^
  File "C:\Users\avandenheuvel\AppData\Local\Programs\Python\Python311\GUI test 1.31.py", line 217, in on_slider_change
    self.time_period = int(value)
                       ^^^^^^^^^^
ValueError: invalid literal for int() with base 10: '456.3440860215054'
Exception in Tkinter callback
Traceback (most recent call last):
  File "C:\Users\avandenheuvel\AppData\Local\Programs\Python\Python311\Lib\tkinter\__init__.py", line 1948, in __call__
    return self.func(*args)
           ^^^^^^^^^^^^^^^^
  File "C:\Users\avandenheuvel\AppData\Local\Programs\Python\Python311\GUI test 1.31.py", line 217, in on_slider_change
    self.time_period = int(value)
                       ^^^^^^^^^^
ValueError: invalid literal for int() with base 10: '612.7956989247313'
Exception in Tkinter callback
Traceback (most recent call last):
  File "C:\Users\avandenheuvel\AppData\Local\Programs\Python\Python311\Lib\tkinter\__init__.py", line 1948, in __call__
    return self.func(*args)
           ^^^^^^^^^^^^^^^^
  File "C:\Users\avandenheuvel\AppData\Local\Programs\Python\Python311\GUI test 1.31.py", line 217, in on_slider_change
    self.time_period = int(value)
                       ^^^^^^^^^^
ValueError: invalid literal for int() with base 10: '623.2258064516129'

= RESTART: C:\Users\avandenheuvel\AppData\Local\Programs\Python\Python311\GUI test 1.31.py

= RESTART: C:\Users\avandenheuvel\AppData\Local\Programs\Python\Python311\GUI test 1.31.py
Traceback (most recent call last):
  File "C:\Users\avandenheuvel\AppData\Local\Programs\Python\Python311\GUI test 1.31.py", line 274, in <module>
    app = TemperatureControllerApp()
  File "C:\Users\avandenheuvel\AppData\Local\Programs\Python\Python311\GUI test 1.31.py", line 26, in __init__
    self.create_main_screen()
  File "C:\Users\avandenheuvel\AppData\Local\Programs\Python\Python311\GUI test 1.31.py", line 99, in create_main_screen
    self.label_slider_value = ttk.Label(self.main_screen, text="Slider Value: " + str(self.time_period.get()))
AttributeError: 'int' object has no attribute 'get'
Exception in Tkinter callback
Traceback (most recent call last):
  File "C:\Users\avandenheuvel\AppData\Local\Programs\Python\Python311\Lib\tkinter\__init__.py", line 1948, in __call__
    return self.func(*args)
           ^^^^^^^^^^^^^^^^
  File "C:\Users\avandenheuvel\AppData\Local\Programs\Python\Python311\GUI test 1.31.py", line 220, in on_slider_change
    self.label_slider_value.config(text="Slider Value: " + str(int(value)))  # Update the label's text
    ^^^^^^^^^^^^^^^^^^^^^^^
  File "C:\Users\avandenheuvel\AppData\Local\Programs\Python\Python311\Lib\tkinter\__init__.py", line 2410, in __getattr__
    return getattr(self.tk, attr)
           ^^^^^^^^^^^^^^^^^^^^^^
AttributeError: '_tkinter.tkapp' object has no attribute 'label_slider_value'
Exception in Tkinter callback
Traceback (most recent call last):
  File "C:\Users\avandenheuvel\AppData\Local\Programs\Python\Python311\Lib\tkinter\__init__.py", line 1948, in __call__
    return self.func(*args)
           ^^^^^^^^^^^^^^^^
  File "C:\Users\avandenheuvel\AppData\Local\Programs\Python\Python311\GUI test 1.31.py", line 220, in on_slider_change
    self.label_slider_value.config(text="Slider Value: " + str(int(value)))  # Update the label's text
    ^^^^^^^^^^^^^^^^^^^^^^^
  File "C:\Users\avandenheuvel\AppData\Local\Programs\Python\Python311\Lib\tkinter\__init__.py", line 2410, in __getattr__
    return getattr(self.tk, attr)
           ^^^^^^^^^^^^^^^^^^^^^^
AttributeError: '_tkinter.tkapp' object has no attribute 'label_slider_value'
Exception in Tkinter callback
Traceback (most recent call last):
  File "C:\Users\avandenheuvel\AppData\Local\Programs\Python\Python311\Lib\tkinter\__init__.py", line 1948, in __call__
    return self.func(*args)
           ^^^^^^^^^^^^^^^^
  File "C:\Users\avandenheuvel\AppData\Local\Programs\Python\Python311\GUI test 1.31.py", line 220, in on_slider_change
    self.label_slider_value.config(text="Slider Value: " + str(int(value)))  # Update the label's text
    ^^^^^^^^^^^^^^^^^^^^^^^
  File "C:\Users\avandenheuvel\AppData\Local\Programs\Python\Python311\Lib\tkinter\__init__.py", line 2410, in __getattr__
    return getattr(self.tk, attr)
           ^^^^^^^^^^^^^^^^^^^^^^
AttributeError: '_tkinter.tkapp' object has no attribute 'label_slider_value'
Exception in Tkinter callback
Traceback (most recent call last):
  File "C:\Users\avandenheuvel\AppData\Local\Programs\Python\Python311\Lib\tkinter\__init__.py", line 1948, in __call__
    return self.func(*args)
           ^^^^^^^^^^^^^^^^
  File "C:\Users\avandenheuvel\AppData\Local\Programs\Python\Python311\GUI test 1.31.py", line 220, in on_slider_change
    self.label_slider_value.config(text="Slider Value: " + str(int(value)))  # Update the label's text
    ^^^^^^^^^^^^^^^^^^^^^^^
  File "C:\Users\avandenheuvel\AppData\Local\Programs\Python\Python311\Lib\tkinter\__init__.py", line 2410, in __getattr__
    return getattr(self.tk, attr)
           ^^^^^^^^^^^^^^^^^^^^^^
AttributeError: '_tkinter.tkapp' object has no attribute 'label_slider_value'
Exception in Tkinter callback
Traceback (most recent call last):
  File "C:\Users\avandenheuvel\AppData\Local\Programs\Python\Python311\Lib\tkinter\__init__.py", line 1948, in __call__
    return self.func(*args)
           ^^^^^^^^^^^^^^^^
  File "C:\Users\avandenheuvel\AppData\Local\Programs\Python\Python311\GUI test 1.31.py", line 220, in on_slider_change
    self.label_slider_value.config(text="Slider Value: " + str(int(value)))  # Update the label's text
    ^^^^^^^^^^^^^^^^^^^^^^^
  File "C:\Users\avandenheuvel\AppData\Local\Programs\Python\Python311\Lib\tkinter\__init__.py", line 2410, in __getattr__
    return getattr(self.tk, attr)
           ^^^^^^^^^^^^^^^^^^^^^^
AttributeError: '_tkinter.tkapp' object has no attribute 'label_slider_value'
Exception in Tkinter callback
Traceback (most recent call last):
  File "C:\Users\avandenheuvel\AppData\Local\Programs\Python\Python311\Lib\tkinter\__init__.py", line 1948, in __call__
    return self.func(*args)
           ^^^^^^^^^^^^^^^^
  File "C:\Users\avandenheuvel\AppData\Local\Programs\Python\Python311\GUI test 1.31.py", line 220, in on_slider_change
    self.label_slider_value.config(text="Slider Value: " + str(int(value)))  # Update the label's text
    ^^^^^^^^^^^^^^^^^^^^^^^
  File "C:\Users\avandenheuvel\AppData\Local\Programs\Python\Python311\Lib\tkinter\__init__.py", line 2410, in __getattr__
    return getattr(self.tk, attr)
           ^^^^^^^^^^^^^^^^^^^^^^
AttributeError: '_tkinter.tkapp' object has no attribute 'label_slider_value'
Exception in Tkinter callback
Traceback (most recent call last):
  File "C:\Users\avandenheuvel\AppData\Local\Programs\Python\Python311\Lib\tkinter\__init__.py", line 1948, in __call__
    return self.func(*args)
           ^^^^^^^^^^^^^^^^
  File "C:\Users\avandenheuvel\AppData\Local\Programs\Python\Python311\GUI test 1.31.py", line 220, in on_slider_change
    self.label_slider_value.config(text="Slider Value: " + str(int(value)))  # Update the label's text
    ^^^^^^^^^^^^^^^^^^^^^^^
  File "C:\Users\avandenheuvel\AppData\Local\Programs\Python\Python311\Lib\tkinter\__init__.py", line 2410, in __getattr__
    return getattr(self.tk, attr)
           ^^^^^^^^^^^^^^^^^^^^^^
AttributeError: '_tkinter.tkapp' object has no attribute 'label_slider_value'
Exception in Tkinter callback
Traceback (most recent call last):
  File "C:\Users\avandenheuvel\AppData\Local\Programs\Python\Python311\Lib\tkinter\__init__.py", line 1948, in __call__
    return self.func(*args)
           ^^^^^^^^^^^^^^^^
  File "C:\Users\avandenheuvel\AppData\Local\Programs\Python\Python311\GUI test 1.31.py", line 220, in on_slider_change
    self.label_slider_value.config(text="Slider Value: " + str(int(value)))  # Update the label's text
    ^^^^^^^^^^^^^^^^^^^^^^^
  File "C:\Users\avandenheuvel\AppData\Local\Programs\Python\Python311\Lib\tkinter\__init__.py", line 2410, in __getattr__
    return getattr(self.tk, attr)
           ^^^^^^^^^^^^^^^^^^^^^^
AttributeError: '_tkinter.tkapp' object has no attribute 'label_slider_value'
Exception in Tkinter callback
Traceback (most recent call last):
  File "C:\Users\avandenheuvel\AppData\Local\Programs\Python\Python311\Lib\tkinter\__init__.py", line 1948, in __call__
    return self.func(*args)
           ^^^^^^^^^^^^^^^^
  File "C:\Users\avandenheuvel\AppData\Local\Programs\Python\Python311\GUI test 1.31.py", line 220, in on_slider_change
    self.label_slider_value.config(text="Slider Value: " + str(int(value)))  # Update the label's text
    ^^^^^^^^^^^^^^^^^^^^^^^
  File "C:\Users\avandenheuvel\AppData\Local\Programs\Python\Python311\Lib\tkinter\__init__.py", line 2410, in __getattr__
    return getattr(self.tk, attr)
           ^^^^^^^^^^^^^^^^^^^^^^
AttributeError: '_tkinter.tkapp' object has no attribute 'label_slider_value'
Exception in Tkinter callback
Traceback (most recent call last):
  File "C:\Users\avandenheuvel\AppData\Local\Programs\Python\Python311\Lib\tkinter\__init__.py", line 1948, in __call__
    return self.func(*args)
           ^^^^^^^^^^^^^^^^
  File "C:\Users\avandenheuvel\AppData\Local\Programs\Python\Python311\GUI test 1.31.py", line 220, in on_slider_change
    self.label_slider_value.config(text="Slider Value: " + str(int(value)))  # Update the label's text
    ^^^^^^^^^^^^^^^^^^^^^^^
  File "C:\Users\avandenheuvel\AppData\Local\Programs\Python\Python311\Lib\tkinter\__init__.py", line 2410, in __getattr__
    return getattr(self.tk, attr)
           ^^^^^^^^^^^^^^^^^^^^^^
AttributeError: '_tkinter.tkapp' object has no attribute 'label_slider_value'
Exception in Tkinter callback
Traceback (most recent call last):
  File "C:\Users\avandenheuvel\AppData\Local\Programs\Python\Python311\Lib\tkinter\__init__.py", line 1948, in __call__
    return self.func(*args)
           ^^^^^^^^^^^^^^^^
  File "C:\Users\avandenheuvel\AppData\Local\Programs\Python\Python311\GUI test 1.31.py", line 220, in on_slider_change
    self.label_slider_value.config(text="Slider Value: " + str(int(value)))  # Update the label's text
    ^^^^^^^^^^^^^^^^^^^^^^^
  File "C:\Users\avandenheuvel\AppData\Local\Programs\Python\Python311\Lib\tkinter\__init__.py", line 2410, in __getattr__
    return getattr(self.tk, attr)
           ^^^^^^^^^^^^^^^^^^^^^^
AttributeError: '_tkinter.tkapp' object has no attribute 'label_slider_value'
Exception in Tkinter callback
Traceback (most recent call last):
  File "C:\Users\avandenheuvel\AppData\Local\Programs\Python\Python311\Lib\tkinter\__init__.py", line 1948, in __call__
    return self.func(*args)
           ^^^^^^^^^^^^^^^^
  File "C:\Users\avandenheuvel\AppData\Local\Programs\Python\Python311\GUI test 1.31.py", line 220, in on_slider_change
    self.label_slider_value.config(text="Slider Value: " + str(int(value)))  # Update the label's text
    ^^^^^^^^^^^^^^^^^^^^^^^
  File "C:\Users\avandenheuvel\AppData\Local\Programs\Python\Python311\Lib\tkinter\__init__.py", line 2410, in __getattr__
    return getattr(self.tk, attr)
           ^^^^^^^^^^^^^^^^^^^^^^
AttributeError: '_tkinter.tkapp' object has no attribute 'label_slider_value'
Exception in Tkinter callback
Traceback (most recent call last):
  File "C:\Users\avandenheuvel\AppData\Local\Programs\Python\Python311\Lib\tkinter\__init__.py", line 1948, in __call__
    return self.func(*args)
           ^^^^^^^^^^^^^^^^
  File "C:\Users\avandenheuvel\AppData\Local\Programs\Python\Python311\GUI test 1.31.py", line 220, in on_slider_change
    self.label_slider_value.config(text="Slider Value: " + str(int(value)))  # Update the label's text
    ^^^^^^^^^^^^^^^^^^^^^^^
  File "C:\Users\avandenheuvel\AppData\Local\Programs\Python\Python311\Lib\tkinter\__init__.py", line 2410, in __getattr__
    return getattr(self.tk, attr)
           ^^^^^^^^^^^^^^^^^^^^^^
AttributeError: '_tkinter.tkapp' object has no attribute 'label_slider_value'
Exception in Tkinter callback
Traceback (most recent call last):
  File "C:\Users\avandenheuvel\AppData\Local\Programs\Python\Python311\Lib\tkinter\__init__.py", line 1948, in __call__
    return self.func(*args)
           ^^^^^^^^^^^^^^^^
  File "C:\Users\avandenheuvel\AppData\Local\Programs\Python\Python311\GUI test 1.31.py", line 220, in on_slider_change
    self.label_slider_value.config(text="Slider Value: " + str(int(value)))  # Update the label's text
    ^^^^^^^^^^^^^^^^^^^^^^^
  File "C:\Users\avandenheuvel\AppData\Local\Programs\Python\Python311\Lib\tkinter\__init__.py", line 2410, in __getattr__
    return getattr(self.tk, attr)
           ^^^^^^^^^^^^^^^^^^^^^^
AttributeError: '_tkinter.tkapp' object has no attribute 'label_slider_value'
Exception in Tkinter callback
Traceback (most recent call last):
  File "C:\Users\avandenheuvel\AppData\Local\Programs\Python\Python311\Lib\tkinter\__init__.py", line 1948, in __call__
    return self.func(*args)
           ^^^^^^^^^^^^^^^^
  File "C:\Users\avandenheuvel\AppData\Local\Programs\Python\Python311\GUI test 1.31.py", line 220, in on_slider_change
    self.label_slider_value.config(text="Slider Value: " + str(int(value)))  # Update the label's text
    ^^^^^^^^^^^^^^^^^^^^^^^
  File "C:\Users\avandenheuvel\AppData\Local\Programs\Python\Python311\Lib\tkinter\__init__.py", line 2410, in __getattr__
    return getattr(self.tk, attr)
           ^^^^^^^^^^^^^^^^^^^^^^
AttributeError: '_tkinter.tkapp' object has no attribute 'label_slider_value'
Exception in Tkinter callback
Traceback (most recent call last):
  File "C:\Users\avandenheuvel\AppData\Local\Programs\Python\Python311\Lib\tkinter\__init__.py", line 1948, in __call__
    return self.func(*args)
           ^^^^^^^^^^^^^^^^
  File "C:\Users\avandenheuvel\AppData\Local\Programs\Python\Python311\GUI test 1.31.py", line 220, in on_slider_change
    self.label_slider_value.config(text="Slider Value: " + str(int(value)))  # Update the label's text
    ^^^^^^^^^^^^^^^^^^^^^^^
  File "C:\Users\avandenheuvel\AppData\Local\Programs\Python\Python311\Lib\tkinter\__init__.py", line 2410, in __getattr__
    return getattr(self.tk, attr)
           ^^^^^^^^^^^^^^^^^^^^^^
AttributeError: '_tkinter.tkapp' object has no attribute 'label_slider_value'
Exception in Tkinter callback
Traceback (most recent call last):
  File "C:\Users\avandenheuvel\AppData\Local\Programs\Python\Python311\Lib\tkinter\__init__.py", line 1948, in __call__
    return self.func(*args)
           ^^^^^^^^^^^^^^^^
  File "C:\Users\avandenheuvel\AppData\Local\Programs\Python\Python311\GUI test 1.31.py", line 220, in on_slider_change
    self.label_slider_value.config(text="Slider Value: " + str(int(value)))  # Update the label's text
    ^^^^^^^^^^^^^^^^^^^^^^^
  File "C:\Users\avandenheuvel\AppData\Local\Programs\Python\Python311\Lib\tkinter\__init__.py", line 2410, in __getattr__
    return getattr(self.tk, attr)
           ^^^^^^^^^^^^^^^^^^^^^^
AttributeError: '_tkinter.tkapp' object has no attribute 'label_slider_value'
Exception in Tkinter callback
Traceback (most recent call last):
  File "C:\Users\avandenheuvel\AppData\Local\Programs\Python\Python311\Lib\tkinter\__init__.py", line 1948, in __call__
    return self.func(*args)
           ^^^^^^^^^^^^^^^^
  File "C:\Users\avandenheuvel\AppData\Local\Programs\Python\Python311\GUI test 1.31.py", line 220, in on_slider_change
    self.label_slider_value.config(text="Slider Value: " + str(int(value)))  # Update the label's text
    ^^^^^^^^^^^^^^^^^^^^^^^
  File "C:\Users\avandenheuvel\AppData\Local\Programs\Python\Python311\Lib\tkinter\__init__.py", line 2410, in __getattr__
    return getattr(self.tk, attr)
           ^^^^^^^^^^^^^^^^^^^^^^
AttributeError: '_tkinter.tkapp' object has no attribute 'label_slider_value'
Exception in Tkinter callback
Traceback (most recent call last):
  File "C:\Users\avandenheuvel\AppData\Local\Programs\Python\Python311\Lib\tkinter\__init__.py", line 1948, in __call__
    return self.func(*args)
           ^^^^^^^^^^^^^^^^
  File "C:\Users\avandenheuvel\AppData\Local\Programs\Python\Python311\GUI test 1.31.py", line 220, in on_slider_change
    self.label_slider_value.config(text="Slider Value: " + str(int(value)))  # Update the label's text
    ^^^^^^^^^^^^^^^^^^^^^^^
  File "C:\Users\avandenheuvel\AppData\Local\Programs\Python\Python311\Lib\tkinter\__init__.py", line 2410, in __getattr__
    return getattr(self.tk, attr)
           ^^^^^^^^^^^^^^^^^^^^^^
AttributeError: '_tkinter.tkapp' object has no attribute 'label_slider_value'
Exception in Tkinter callback
Traceback (most recent call last):
  File "C:\Users\avandenheuvel\AppData\Local\Programs\Python\Python311\Lib\tkinter\__init__.py", line 1948, in __call__
    return self.func(*args)
           ^^^^^^^^^^^^^^^^
  File "C:\Users\avandenheuvel\AppData\Local\Programs\Python\Python311\GUI test 1.31.py", line 220, in on_slider_change
    self.label_slider_value.config(text="Slider Value: " + str(int(value)))  # Update the label's text
    ^^^^^^^^^^^^^^^^^^^^^^^
  File "C:\Users\avandenheuvel\AppData\Local\Programs\Python\Python311\Lib\tkinter\__init__.py", line 2410, in __getattr__
    return getattr(self.tk, attr)
           ^^^^^^^^^^^^^^^^^^^^^^
AttributeError: '_tkinter.tkapp' object has no attribute 'label_slider_value'
Exception in Tkinter callback
Traceback (most recent call last):
  File "C:\Users\avandenheuvel\AppData\Local\Programs\Python\Python311\Lib\tkinter\__init__.py", line 1948, in __call__
    return self.func(*args)
           ^^^^^^^^^^^^^^^^
  File "C:\Users\avandenheuvel\AppData\Local\Programs\Python\Python311\GUI test 1.31.py", line 220, in on_slider_change
    self.label_slider_value.config(text="Slider Value: " + str(int(value)))  # Update the label's text
    ^^^^^^^^^^^^^^^^^^^^^^^
  File "C:\Users\avandenheuvel\AppData\Local\Programs\Python\Python311\Lib\tkinter\__init__.py", line 2410, in __getattr__
    return getattr(self.tk, attr)
           ^^^^^^^^^^^^^^^^^^^^^^
AttributeError: '_tkinter.tkapp' object has no attribute 'label_slider_value'
Exception in Tkinter callback
Traceback (most recent call last):
  File "C:\Users\avandenheuvel\AppData\Local\Programs\Python\Python311\Lib\tkinter\__init__.py", line 1948, in __call__
    return self.func(*args)
           ^^^^^^^^^^^^^^^^
  File "C:\Users\avandenheuvel\AppData\Local\Programs\Python\Python311\GUI test 1.31.py", line 220, in on_slider_change
    self.label_slider_value.config(text="Slider Value: " + str(int(value)))  # Update the label's text
    ^^^^^^^^^^^^^^^^^^^^^^^
  File "C:\Users\avandenheuvel\AppData\Local\Programs\Python\Python311\Lib\tkinter\__init__.py", line 2410, in __getattr__
    return getattr(self.tk, attr)
           ^^^^^^^^^^^^^^^^^^^^^^
AttributeError: '_tkinter.tkapp' object has no attribute 'label_slider_value'
Exception in Tkinter callback
Traceback (most recent call last):
  File "C:\Users\avandenheuvel\AppData\Local\Programs\Python\Python311\Lib\tkinter\__init__.py", line 1948, in __call__
    return self.func(*args)
           ^^^^^^^^^^^^^^^^
  File "C:\Users\avandenheuvel\AppData\Local\Programs\Python\Python311\GUI test 1.31.py", line 220, in on_slider_change
    self.label_slider_value.config(text="Slider Value: " + str(int(value)))  # Update the label's text
    ^^^^^^^^^^^^^^^^^^^^^^^
  File "C:\Users\avandenheuvel\AppData\Local\Programs\Python\Python311\Lib\tkinter\__init__.py", line 2410, in __getattr__
    return getattr(self.tk, attr)
           ^^^^^^^^^^^^^^^^^^^^^^
AttributeError: '_tkinter.tkapp' object has no attribute 'label_slider_value'
Exception in Tkinter callback
Traceback (most recent call last):
  File "C:\Users\avandenheuvel\AppData\Local\Programs\Python\Python311\Lib\tkinter\__init__.py", line 1948, in __call__
    return self.func(*args)
           ^^^^^^^^^^^^^^^^
  File "C:\Users\avandenheuvel\AppData\Local\Programs\Python\Python311\GUI test 1.31.py", line 220, in on_slider_change
    self.label_slider_value.config(text="Slider Value: " + str(int(value)))  # Update the label's text
    ^^^^^^^^^^^^^^^^^^^^^^^
  File "C:\Users\avandenheuvel\AppData\Local\Programs\Python\Python311\Lib\tkinter\__init__.py", line 2410, in __getattr__
    return getattr(self.tk, attr)
           ^^^^^^^^^^^^^^^^^^^^^^
AttributeError: '_tkinter.tkapp' object has no attribute 'label_slider_value'
Exception in Tkinter callback
Traceback (most recent call last):
  File "C:\Users\avandenheuvel\AppData\Local\Programs\Python\Python311\Lib\tkinter\__init__.py", line 1948, in __call__
    return self.func(*args)
           ^^^^^^^^^^^^^^^^
  File "C:\Users\avandenheuvel\AppData\Local\Programs\Python\Python311\GUI test 1.31.py", line 220, in on_slider_change
    self.label_slider_value.config(text="Slider Value: " + str(int(value)))  # Update the label's text
    ^^^^^^^^^^^^^^^^^^^^^^^
  File "C:\Users\avandenheuvel\AppData\Local\Programs\Python\Python311\Lib\tkinter\__init__.py", line 2410, in __getattr__
    return getattr(self.tk, attr)
           ^^^^^^^^^^^^^^^^^^^^^^
AttributeError: '_tkinter.tkapp' object has no attribute 'label_slider_value'
Exception in Tkinter callback
Traceback (most recent call last):
  File "C:\Users\avandenheuvel\AppData\Local\Programs\Python\Python311\Lib\tkinter\__init__.py", line 1948, in __call__
    return self.func(*args)
           ^^^^^^^^^^^^^^^^
  File "C:\Users\avandenheuvel\AppData\Local\Programs\Python\Python311\GUI test 1.31.py", line 220, in on_slider_change
    self.label_slider_value.config(text="Slider Value: " + str(int(value)))  # Update the label's text
    ^^^^^^^^^^^^^^^^^^^^^^^
  File "C:\Users\avandenheuvel\AppData\Local\Programs\Python\Python311\Lib\tkinter\__init__.py", line 2410, in __getattr__
    return getattr(self.tk, attr)
           ^^^^^^^^^^^^^^^^^^^^^^
AttributeError: '_tkinter.tkapp' object has no attribute 'label_slider_value'

= RESTART: C:\Users\avandenheuvel\AppData\Local\Programs\Python\Python311\GUI test 1.31.py

= RESTART: C:\Users\avandenheuvel\AppData\Local\Programs\Python\Python311\GUI test 1.31.py
Traceback (most recent call last):
  File "C:\Users\avandenheuvel\AppData\Local\Programs\Python\Python311\GUI test 1.31.py", line 275, in <module>
    app = TemperatureControllerApp()
  File "C:\Users\avandenheuvel\AppData\Local\Programs\Python\Python311\GUI test 1.31.py", line 29, in __init__
    self.label_slider_value = ttk.Label(self.main_screen, text="Slider Value: " + str(self.time_period.get()))
AttributeError: 'int' object has no attribute 'get'
Exception in Tkinter callback
Traceback (most recent call last):
  File "C:\Users\avandenheuvel\AppData\Local\Programs\Python\Python311\Lib\tkinter\__init__.py", line 1948, in __call__
    return self.func(*args)
           ^^^^^^^^^^^^^^^^
  File "C:\Users\avandenheuvel\AppData\Local\Programs\Python\Python311\GUI test 1.31.py", line 222, in on_slider_change
    self.update_graph()
  File "C:\Users\avandenheuvel\AppData\Local\Programs\Python\Python311\GUI test 1.31.py", line 207, in update_graph
    self.graph_ax.clear()
    ^^^^^^^^^^^^^
  File "C:\Users\avandenheuvel\AppData\Local\Programs\Python\Python311\Lib\tkinter\__init__.py", line 2410, in __getattr__
    return getattr(self.tk, attr)
           ^^^^^^^^^^^^^^^^^^^^^^
AttributeError: '_tkinter.tkapp' object has no attribute 'graph_ax'
Exception in Tkinter callback
Traceback (most recent call last):
  File "C:\Users\avandenheuvel\AppData\Local\Programs\Python\Python311\Lib\tkinter\__init__.py", line 1948, in __call__
    return self.func(*args)
           ^^^^^^^^^^^^^^^^
  File "C:\Users\avandenheuvel\AppData\Local\Programs\Python\Python311\GUI test 1.31.py", line 222, in on_slider_change
    self.update_graph()
  File "C:\Users\avandenheuvel\AppData\Local\Programs\Python\Python311\GUI test 1.31.py", line 207, in update_graph
    self.graph_ax.clear()
    ^^^^^^^^^^^^^
  File "C:\Users\avandenheuvel\AppData\Local\Programs\Python\Python311\Lib\tkinter\__init__.py", line 2410, in __getattr__
    return getattr(self.tk, attr)
           ^^^^^^^^^^^^^^^^^^^^^^
AttributeError: '_tkinter.tkapp' object has no attribute 'graph_ax'
Exception in Tkinter callback
Traceback (most recent call last):
  File "C:\Users\avandenheuvel\AppData\Local\Programs\Python\Python311\Lib\tkinter\__init__.py", line 1948, in __call__
    return self.func(*args)
           ^^^^^^^^^^^^^^^^
  File "C:\Users\avandenheuvel\AppData\Local\Programs\Python\Python311\GUI test 1.31.py", line 222, in on_slider_change
    self.update_graph()
  File "C:\Users\avandenheuvel\AppData\Local\Programs\Python\Python311\GUI test 1.31.py", line 207, in update_graph
    self.graph_ax.clear()
    ^^^^^^^^^^^^^
  File "C:\Users\avandenheuvel\AppData\Local\Programs\Python\Python311\Lib\tkinter\__init__.py", line 2410, in __getattr__
    return getattr(self.tk, attr)
           ^^^^^^^^^^^^^^^^^^^^^^
AttributeError: '_tkinter.tkapp' object has no attribute 'graph_ax'
Exception in Tkinter callback
Traceback (most recent call last):
  File "C:\Users\avandenheuvel\AppData\Local\Programs\Python\Python311\Lib\tkinter\__init__.py", line 1948, in __call__
    return self.func(*args)
           ^^^^^^^^^^^^^^^^
  File "C:\Users\avandenheuvel\AppData\Local\Programs\Python\Python311\GUI test 1.31.py", line 222, in on_slider_change
    self.update_graph()
  File "C:\Users\avandenheuvel\AppData\Local\Programs\Python\Python311\GUI test 1.31.py", line 207, in update_graph
    self.graph_ax.clear()
    ^^^^^^^^^^^^^
  File "C:\Users\avandenheuvel\AppData\Local\Programs\Python\Python311\Lib\tkinter\__init__.py", line 2410, in __getattr__
    return getattr(self.tk, attr)
           ^^^^^^^^^^^^^^^^^^^^^^
AttributeError: '_tkinter.tkapp' object has no attribute 'graph_ax'
Exception in Tkinter callback
Traceback (most recent call last):
  File "C:\Users\avandenheuvel\AppData\Local\Programs\Python\Python311\Lib\tkinter\__init__.py", line 1948, in __call__
    return self.func(*args)
           ^^^^^^^^^^^^^^^^
  File "C:\Users\avandenheuvel\AppData\Local\Programs\Python\Python311\GUI test 1.31.py", line 222, in on_slider_change
    self.update_graph()
  File "C:\Users\avandenheuvel\AppData\Local\Programs\Python\Python311\GUI test 1.31.py", line 207, in update_graph
    self.graph_ax.clear()
    ^^^^^^^^^^^^^
  File "C:\Users\avandenheuvel\AppData\Local\Programs\Python\Python311\Lib\tkinter\__init__.py", line 2410, in __getattr__
    return getattr(self.tk, attr)
           ^^^^^^^^^^^^^^^^^^^^^^
AttributeError: '_tkinter.tkapp' object has no attribute 'graph_ax'
Exception in Tkinter callback
Traceback (most recent call last):
  File "C:\Users\avandenheuvel\AppData\Local\Programs\Python\Python311\Lib\tkinter\__init__.py", line 1948, in __call__
    return self.func(*args)
           ^^^^^^^^^^^^^^^^
  File "C:\Users\avandenheuvel\AppData\Local\Programs\Python\Python311\GUI test 1.31.py", line 222, in on_slider_change
    self.update_graph()
  File "C:\Users\avandenheuvel\AppData\Local\Programs\Python\Python311\GUI test 1.31.py", line 207, in update_graph
    self.graph_ax.clear()
    ^^^^^^^^^^^^^
  File "C:\Users\avandenheuvel\AppData\Local\Programs\Python\Python311\Lib\tkinter\__init__.py", line 2410, in __getattr__
    return getattr(self.tk, attr)
           ^^^^^^^^^^^^^^^^^^^^^^
AttributeError: '_tkinter.tkapp' object has no attribute 'graph_ax'
Exception in Tkinter callback
Traceback (most recent call last):
  File "C:\Users\avandenheuvel\AppData\Local\Programs\Python\Python311\Lib\tkinter\__init__.py", line 1948, in __call__
    return self.func(*args)
           ^^^^^^^^^^^^^^^^
  File "C:\Users\avandenheuvel\AppData\Local\Programs\Python\Python311\GUI test 1.31.py", line 222, in on_slider_change
    self.update_graph()
  File "C:\Users\avandenheuvel\AppData\Local\Programs\Python\Python311\GUI test 1.31.py", line 207, in update_graph
    self.graph_ax.clear()
    ^^^^^^^^^^^^^
  File "C:\Users\avandenheuvel\AppData\Local\Programs\Python\Python311\Lib\tkinter\__init__.py", line 2410, in __getattr__
    return getattr(self.tk, attr)
           ^^^^^^^^^^^^^^^^^^^^^^
AttributeError: '_tkinter.tkapp' object has no attribute 'graph_ax'
Exception in Tkinter callback
Traceback (most recent call last):
  File "C:\Users\avandenheuvel\AppData\Local\Programs\Python\Python311\Lib\tkinter\__init__.py", line 1948, in __call__
    return self.func(*args)
           ^^^^^^^^^^^^^^^^
  File "C:\Users\avandenheuvel\AppData\Local\Programs\Python\Python311\GUI test 1.31.py", line 222, in on_slider_change
    self.update_graph()
  File "C:\Users\avandenheuvel\AppData\Local\Programs\Python\Python311\GUI test 1.31.py", line 207, in update_graph
    self.graph_ax.clear()
    ^^^^^^^^^^^^^
  File "C:\Users\avandenheuvel\AppData\Local\Programs\Python\Python311\Lib\tkinter\__init__.py", line 2410, in __getattr__
    return getattr(self.tk, attr)
           ^^^^^^^^^^^^^^^^^^^^^^
AttributeError: '_tkinter.tkapp' object has no attribute 'graph_ax'
Exception in Tkinter callback
Traceback (most recent call last):
  File "C:\Users\avandenheuvel\AppData\Local\Programs\Python\Python311\Lib\tkinter\__init__.py", line 1948, in __call__
    return self.func(*args)
           ^^^^^^^^^^^^^^^^
  File "C:\Users\avandenheuvel\AppData\Local\Programs\Python\Python311\GUI test 1.31.py", line 222, in on_slider_change
    self.update_graph()
  File "C:\Users\avandenheuvel\AppData\Local\Programs\Python\Python311\GUI test 1.31.py", line 207, in update_graph
    self.graph_ax.clear()
    ^^^^^^^^^^^^^
  File "C:\Users\avandenheuvel\AppData\Local\Programs\Python\Python311\Lib\tkinter\__init__.py", line 2410, in __getattr__
    return getattr(self.tk, attr)
           ^^^^^^^^^^^^^^^^^^^^^^
AttributeError: '_tkinter.tkapp' object has no attribute 'graph_ax'
Exception in Tkinter callback
Traceback (most recent call last):
  File "C:\Users\avandenheuvel\AppData\Local\Programs\Python\Python311\Lib\tkinter\__init__.py", line 1948, in __call__
    return self.func(*args)
           ^^^^^^^^^^^^^^^^
  File "C:\Users\avandenheuvel\AppData\Local\Programs\Python\Python311\GUI test 1.31.py", line 222, in on_slider_change
    self.update_graph()
  File "C:\Users\avandenheuvel\AppData\Local\Programs\Python\Python311\GUI test 1.31.py", line 207, in update_graph
    self.graph_ax.clear()
    ^^^^^^^^^^^^^
  File "C:\Users\avandenheuvel\AppData\Local\Programs\Python\Python311\Lib\tkinter\__init__.py", line 2410, in __getattr__
    return getattr(self.tk, attr)
           ^^^^^^^^^^^^^^^^^^^^^^
AttributeError: '_tkinter.tkapp' object has no attribute 'graph_ax'
Exception in Tkinter callback
Traceback (most recent call last):
  File "C:\Users\avandenheuvel\AppData\Local\Programs\Python\Python311\Lib\tkinter\__init__.py", line 1948, in __call__
    return self.func(*args)
           ^^^^^^^^^^^^^^^^
  File "C:\Users\avandenheuvel\AppData\Local\Programs\Python\Python311\GUI test 1.31.py", line 222, in on_slider_change
    self.update_graph()
  File "C:\Users\avandenheuvel\AppData\Local\Programs\Python\Python311\GUI test 1.31.py", line 207, in update_graph
    self.graph_ax.clear()
    ^^^^^^^^^^^^^
  File "C:\Users\avandenheuvel\AppData\Local\Programs\Python\Python311\Lib\tkinter\__init__.py", line 2410, in __getattr__
    return getattr(self.tk, attr)
           ^^^^^^^^^^^^^^^^^^^^^^
AttributeError: '_tkinter.tkapp' object has no attribute 'graph_ax'
Exception in Tkinter callback
Traceback (most recent call last):
  File "C:\Users\avandenheuvel\AppData\Local\Programs\Python\Python311\Lib\tkinter\__init__.py", line 1948, in __call__
    return self.func(*args)
           ^^^^^^^^^^^^^^^^
  File "C:\Users\avandenheuvel\AppData\Local\Programs\Python\Python311\GUI test 1.31.py", line 222, in on_slider_change
    self.update_graph()
  File "C:\Users\avandenheuvel\AppData\Local\Programs\Python\Python311\GUI test 1.31.py", line 207, in update_graph
    self.graph_ax.clear()
    ^^^^^^^^^^^^^
  File "C:\Users\avandenheuvel\AppData\Local\Programs\Python\Python311\Lib\tkinter\__init__.py", line 2410, in __getattr__
    return getattr(self.tk, attr)
           ^^^^^^^^^^^^^^^^^^^^^^
AttributeError: '_tkinter.tkapp' object has no attribute 'graph_ax'
Exception in Tkinter callback
Traceback (most recent call last):
  File "C:\Users\avandenheuvel\AppData\Local\Programs\Python\Python311\Lib\tkinter\__init__.py", line 1948, in __call__
    return self.func(*args)
           ^^^^^^^^^^^^^^^^
  File "C:\Users\avandenheuvel\AppData\Local\Programs\Python\Python311\GUI test 1.31.py", line 222, in on_slider_change
    self.update_graph()
  File "C:\Users\avandenheuvel\AppData\Local\Programs\Python\Python311\GUI test 1.31.py", line 207, in update_graph
    self.graph_ax.clear()
    ^^^^^^^^^^^^^
  File "C:\Users\avandenheuvel\AppData\Local\Programs\Python\Python311\Lib\tkinter\__init__.py", line 2410, in __getattr__
    return getattr(self.tk, attr)
           ^^^^^^^^^^^^^^^^^^^^^^
AttributeError: '_tkinter.tkapp' object has no attribute 'graph_ax'

= RESTART: C:\Users\avandenheuvel\AppData\Local\Programs\Python\Python311\GUI test 1.31.py
Traceback (most recent call last):
  File "C:\Users\avandenheuvel\AppData\Local\Programs\Python\Python311\GUI test 1.31.py", line 266, in <module>
    app = TemperatureControllerApp()
  File "C:\Users\avandenheuvel\AppData\Local\Programs\Python\Python311\GUI test 1.31.py", line 26, in __init__
    self.create_main_screen()
  File "C:\Users\avandenheuvel\AppData\Local\Programs\Python\Python311\GUI test 1.31.py", line 91, in create_main_screen
    self.label_slider_value = ttk.Label(self.main_screen, text="Slider Value: " + str(self.time_period.get()))
AttributeError: 'int' object has no attribute 'get'
>>> 
= RESTART: C:\Users\avandenheuvel\AppData\Local\Programs\Python\Python311\GUI test 1.31.py
Traceback (most recent call last):
  File "C:\Users\avandenheuvel\AppData\Local\Programs\Python\Python311\GUI test 1.31.py", line 268, in <module>
    app = TemperatureControllerApp()
  File "C:\Users\avandenheuvel\AppData\Local\Programs\Python\Python311\GUI test 1.31.py", line 26, in __init__
    self.create_main_screen()
  File "C:\Users\avandenheuvel\AppData\Local\Programs\Python\Python311\GUI test 1.31.py", line 91, in create_main_screen
    self.label_slider_value = ttk.Label(self.main_screen, text="Slider Value: " + str(self.time_period.get()))
AttributeError: 'int' object has no attribute 'get'
>>> 
= RESTART: C:\Users\avandenheuvel\AppData\Local\Programs\Python\Python311\GUI test 1.31.py
Traceback (most recent call last):
  File "C:\Users\avandenheuvel\AppData\Local\Programs\Python\Python311\GUI test 1.31.py", line 269, in <module>
    app = TemperatureControllerApp()
  File "C:\Users\avandenheuvel\AppData\Local\Programs\Python\Python311\GUI test 1.31.py", line 26, in __init__
    self.create_main_screen()
  File "C:\Users\avandenheuvel\AppData\Local\Programs\Python\Python311\GUI test 1.31.py", line 91, in create_main_screen
    self.label_slider_value = ttk.Label(self.main_screen, text="Slider Value: " + str(self.time_period.get()))
AttributeError: 'int' object has no attribute 'get'
>>> 
= RESTART: C:\Users\avandenheuvel\AppData\Local\Programs\Python\Python311\GUI test 1.31.py
